Error: Certificate generation failed: Saving debug log to /home/letsencrypt/logs/letsencrypt.log
Plugins selected: Authenticator webroot, Installer None
Performing the following challenges:
http-01 challenge for aim.jobai.tech
Using the webroot path /home/runner/static for all unmatched domains.
Waiting for verification...
Challenge failed for domain aim.jobai.tech
http-01 challenge for aim.jobai.tech
Cleaning up challenges
Exiting abnormally:
Traceback (most recent call last):
  File "/home/runner/b6b0e782-95fd-4f59-80d1-274221a443be/.pythonlibs/bin/certbot", line 8, in <module>
    sys.exit(main())
             ^^^^^^
  File "/nix/store/8pa1a0bd8r0yxlb6f5if6lrl031rgbf2-python3.11-certbot-2.9.0/lib/python3.11/site-packages/certbot/main.py", line 19, in main
    return internal_main.main(cli_args)
           ^^^^^^^^^^^^^^^^^^^^^^^^^^^^
  File "/nix/store/8pa1a0bd8r0yxlb6f5if6lrl031rgbf2-python3.11-certbot-2.9.0/lib/python3.11/site-packages/certbot/_internal/main.py", line 1894, in main
    return config.func(config, plugins)
           ^^^^^^^^^^^^^^^^^^^^^^^^^^^^
  File "/nix/store/8pa1a0bd8r0yxlb6f5if6lrl031rgbf2-python3.11-certbot-2.9.0/lib/python3.11/site-packages/certbot/_internal/main.py", line 1600, in certonly
    lineage = _get_and_save_cert(le_client, config, domains, certname, lineage)
              ^^^^^^^^^^^^^^^^^^^^^^^^^^^^^^^^^^^^^^^^^^^^^^^^^^^^^^^^^^^^^^^^^
  File "/nix/store/8pa1a0bd8r0yxlb6f5if6lrl031rgbf2-python3.11-certbot-2.9.0/lib/python3.11/site-packages/certbot/_internal/main.py", line 143, in _get_and_save_cert
    lineage = le_client.obtain_and_enroll_certificate(domains, certname)
              ^^^^^^^^^^^^^^^^^^^^^^^^^^^^^^^^^^^^^^^^^^^^^^^^^^^^^^^^^^
  File "/nix/store/8pa1a0bd8r0yxlb6f5if6lrl031rgbf2-python3.11-certbot-2.9.0/lib/python3.11/site-packages/certbot/_internal/client.py", line 517, in obtain_and_enroll_certificate
    cert, chain, key, _ = self.obtain_certificate(domains)
                          ^^^^^^^^^^^^^^^^^^^^^^^^^^^^^^^^
  File "/nix/store/8pa1a0bd8r0yxlb6f5if6lrl031rgbf2-python3.11-certbot-2.9.0/lib/python3.11/site-packages/certbot/_internal/client.py", line 428, in obtain_certificate
    orderr = self._get_order_and_authorizations(csr.data, self.config.allow_subset_of_names)
             ^^^^^^^^^^^^^^^^^^^^^^^^^^^^^^^^^^^^^^^^^^^^^^^^^^^^^^^^^^^^^^^^^^^^^^^^^^^^^^^
  File "/nix/store/8pa1a0bd8r0yxlb6f5if6lrl031rgbf2-python3.11-certbot-2.9.0/lib/python3.11/site-packages/certbot/_internal/client.py", line 496, in _get_order_and_authorizations
    authzr = self.auth_handler.handle_authorizations(orderr, self.config, best_effort)
             ^^^^^^^^^^^^^^^^^^^^^^^^^^^^^^^^^^^^^^^^^^^^^^^^^^^^^^^^^^^^^^^^^^^^^^^^^
  File "/nix/store/8pa1a0bd8r0yxlb6f5if6lrl031rgbf2-python3.11-certbot-2.9.0/lib/python3.11/site-packages/certbot/_internal/auth_handler.py", line 108, in handle_authorizations
    self._poll_authorizations(authzrs, max_retries, max_time_mins, best_effort)
  File "/nix/store/8pa1a0bd8r0yxlb6f5if6lrl031rgbf2-python3.11-certbot-2.9.0/lib/python3.11/site-packages/certbot/_internal/auth_handler.py", line 212, in _poll_authorizations
    raise errors.AuthorizationError('Some challenges have failed.')
certbot.errors.AuthorizationError: Some challenges have failed.
Ask for help or search for solutions at https://community.letsencrypt.org. See the logfile /home/letsencrypt/logs/letsencrypt.log or re-run Certbot with -v for more details.