During handling of the above exception, another exception occurred:

Traceback (most recent call last):
  File "/home/runner/JobSeekrBot/.pythonlibs/lib/python3.11/site-packages/telegram/ext/_application.py", line 1014, in __run
    loop.run_until_complete(self.stop())
  File "/nix/store/f98g7xbckgqbkagdvpzc2r6lv3h1p9ki-python3-3.11.9/lib/python3.11/asyncio/base_events.py", line 630, in run_until_complete
    self._check_running()
  File "/nix/store/f98g7xbckgqbkagdvpzc2r6lv3h1p9ki-python3-3.11.9/lib/python3.11/asyncio/base_events.py", line 589, in _check_running
    raise RuntimeError('This event loop is already running')
RuntimeError: This event loop is already running

During handling of the above exception, another exception occurred:

Traceback (most recent call last):
  File "/home/runner/JobSeekrBot/main.py", line 50, in <module>
    asyncio.run(main())
  File "/nix/store/f98g7xbckgqbkagdvpzc2r6lv3h1p9ki-python3-3.11.9/lib/python3.11/asyncio/runners.py", line 190, in run
    return runner.run(main)
           ^^^^^^^^^^^^^^^^
  File "/nix/store/f98g7xbckgqbkagdvpzc2r6lv3h1p9ki-python3-3.11.9/lib/python3.11/asyncio/runners.py", line 118, in run
    return self._loop.run_until_complete(task)
           ^^^^^^^^^^^^^^^^^^^^^^^^^^^^^^^^^^^
  File "/nix/store/f98g7xbckgqbkagdvpzc2r6lv3h1p9ki-python3-3.11.9/lib/python3.11/asyncio/base_events.py", line 654, in run_until_complete
    return future.result()
           ^^^^^^^^^^^^^^^
  File "/home/runner/JobSeekrBot/main.py", line 39, in main
    await asyncio.gather(
  File "/home/runner/JobSeekrBot/main.py", line 31, in run_telegram_bot
    await application.run_polling(allowed_updates=Update.ALL_TYPES)
          ^^^^^^^^^^^^^^^^^^^^^^^^^^^^^^^^^^^^^^^^^^^^^^^^^^^^^^^^^
  File "/home/runner/JobSeekrBot/.pythonlibs/lib/python3.11/site-packages/telegram/ext/_application.py", line 818, in run_polling
    return self.__run(
           ^^^^^^^^^^^
  File "/home/runner/JobSeekrBot/.pythonlibs/lib/python3.11/site-packages/telegram/ext/_application.py", line 1022, in __run
    loop.close()
  File "/nix/store/f98g7xbckgqbkagdvpzc2r6lv3h1p9ki-python3-3.11.9/lib/python3.11/asyncio/unix_events.py", line 68, in close
    super().close()
  File "/nix/store/f98g7xbckgqbkagdvpzc2r6lv3h1p9ki-python3-3.11.9/lib/python3.11/asyncio/selector_events.py", line 88, in close
    raise RuntimeError("Cannot close a running event loop")
RuntimeError: Cannot close a running event loop
sys:1: RuntimeWarning: coroutine 'Application.stop' was never awaited
sys:1: RuntimeWarning: coroutine 'Application.initialize' was never awaited
